Workbook
Name SKU_LIST: CATALOGO!$A$6:$A$105

Sheet INICIO
A1: KIT DE DECISIONES · v0.3
A2: Uso semanal para inventario, precio y caja. Funciona sin Python, red ni suscripciones.
B4: EJEMPLO SINTÉTICO · Todos los productos, importes y referencias son ficticios y no han sido aprobados por un cliente real.
B7: 1 · CONFIGURA
B8: Define fecha de corte, ventanas, objetivo de margen y límites de caja. Confirma SI solo después de revisar cada política y la cobertura completa.
B10: 2 · CAPTURA
B11: CATALOGO: economía por SKU. VENTAS: un agregado por fecha y SKU. STOCK: conteo, tránsito y escenario elegido. CAJA: obligaciones existentes; no dupliques compras propuestas.
B13: 3 · REVISA
B14: DECISIONES explica por SKU qué falta, la propuesta condicional y la acción. FLUJO_13_SEMANAS muestra el pago completo de cada compra elegida en su semana.
B16: 4 · DECIDE EN REUNIÓN
B17: La hoja nunca ordena. Revisa evidencia, margen, cantidad, fecha de pago, presupuesto y piso protegido; documenta fuera del archivo quién aprueba.
B21: LÍMITES Y USO SEGURO
B22: Capacidad: 100 SKUs, 1,000 agregados fecha-SKU, 250 movimientos de caja y 13 semanas. Si tus datos exceden un límite, no omitas ni pegues fuera de la tabla: conserva el archivo fuente y solicita una ampliación o un proceso revisado. No captures nombres, correos, teléfonos, domicilios, credenciales ni datos de clientes. Los importes monetarios están en pesos MXN. La proyección muestra cierres semanales; el saldo dentro de la semana puede ser peor. Cada compra se paga completa en una fecha; concilia por separado los pagos divididos.
B28: Alcance: herramienta analítica para conversación y preparación de decisiones. No es ERP, CRM, contabilidad, conciliación bancaria ni orden de compra. No estima elasticidad, impuestos ni causalidad de ventas. Una propuesta depende de los datos y declaraciones visibles.

Sheet CONFIG
A1: CONFIGURACIÓN
A2: Azul = captura editable · Verde = vínculo entre hojas · Negro = cálculo. Blanco significa desconocido; cero es un valor explícito.
A3: Tipo de archivo | B3: EJEMPLO_SINTETICO | C3: Marcador técnico; no modificar.
A5: Fecha de corte | B5: 46286 | C5: Último día incluido. El flujo inicia al día siguiente.
A6: Días de observación | B6: 28 | C6: Ventana completa de disponibilidad y ventas.
A7: Días de seguridad | B7: 7 | C7: Política provisional; revisar antes de confirmar SI.
A8: Margen contribución objetivo | B8: 0.45 | C8: Sobre precio, después de comisión y costos variables capturados.
A9: Caja inicial (MXN pesos) | B9: 80000 | C9: Saldo reconciliado a la fecha de corte.
A10: Piso protegido (MXN pesos) | B10: 40000 | C10: Mínimo de cierre semanal aceptado.
A11: Tope de compras (MXN pesos) | B11: 30000 | C11: Tope adicional antes de propuestas.
A12: Política revisada | B12: SI | C12: SI confirma que lead time, seguridad, MOQ y múltiplos fueron revisados.
A13: Plan de caja completo | B13: SI | C13: SI confirma cobertura de obligaciones conocidas para 91 días.
A14: Ventas completas | B14: SI | C14: SI confirma cobertura de ventas para toda la ventana.
A17: Confirmar SI es una declaración del operador, no una inferencia de la hoja. Si un dato monetario o de cobertura es desconocido, déjalo en blanco o conserva NO; nunca uses cero como sustituto.

Sheet CATALOGO
A1: CATÁLOGO Y ECONOMÍA UNITARIA
A2: Azul = captura editable · Verde = vínculo entre hojas · Negro = cálculo. Blanco significa desconocido; cero es un valor explícito. El precio objetivo no incorpora impuestos ni elasticidad.
A5: SKU | B5: Producto | C5: Categoría | D5: Color | E5: Talla | F5: Estado | G5: Precio lista (MXN pesos) | H5: Costo compra/u (MXN pesos) | I5: Flete entrada/u (MXN pesos) | J5: Empaque/u (MXN pesos) | K5: Comisión | L5: Otro variable/u (MXN pesos) | M5: Lead días | N5: MOQ | O5: Múltiplo pack | P5: Costo variable/u (MXN pesos) | Q5: Contribución/u (MXN pesos) | R5: Margen contribución | S5: Precio objetivo (MXN pesos) | T5: Calidad fila | U5: Estado precio
A6: PIL-NEGRO | B6: Calcetín Pilates Grip | C6: Calcetines Pilates | D6: Negro | E6: Unitalla | F6: ACTIVO | G6: 299 | H6: 82 | I6: 8 | J6: 9 | K6: 0.08 | L6: 5 | M6: 14 | N6: 24 | O6: 12 | P6: =IFERROR(IF(A6="","",IF(OR(COUNT(H6:J6)+COUNT(L6)<4,H6<0,I6<0,J6<0,L6<0,ABS(H6)>1000000000,ABS(I6)>1000000000,ABS(J6)>1000000000,ABS(L6)>1000000000),"",SUM(H6:J6,L6))),"") -> 104 | Q6: =IF(T6<>"OK","",G6*(1-K6)-P6) -> 171.08 | R6: =IF(OR(G6="",G6=0,Q6=""),"",Q6/G6) -> 0.57217391 | S6: =IF(OR(T6<>"OK",P6="",K6="",CONFIG!$B$8="",CONFIG!$B$8<0,CONFIG!$B$8>=1),"",IF(1-K6-CONFIG!$B$8<=0,"",ROUNDUP(ROUND(P6/(1-K6-CONFIG!$B$8),10),2))) -> 221.28 | T6: =IFERROR(IF(A6="","",IF(COUNTIF($A$6:$A$105,A6)>1,"DUPLICADO SKU",IF(OR(B6="",C6="",F6="",G6="",K6="",M6="",N6="",O6=""),"FALTA CAMPO",IF(COUNT(H6:J6)+COUNT(L6)<4,"COSTO INCOMPLETO",IF(OR(G6<=0,H6<0,I6<0,J6<0,L6<0,ABS(G6)>1000000000,ABS(H6)>1000000000,ABS(I6)>1000000000,ABS(J6)>1000000000,ABS(L6)>1000000000,ROUND(G6,2)<>G6,ROUND(H6,2)<>H6,ROUND(I6,2)<>I6,ROUND(J6,2)<>J6,ROUND(L6,2)<>L6,K6<0,K6>=1,M6<0,M6>3650,N6<=0,N6>1000000,O6<=0,O6>1000000),"REVISAR VALOR","OK"))))),"REVISAR VALOR") -> OK | U6: =IF(A6="","",IF(OR(P6="",K6="",CONFIG!$B$8=""),"FALTA COSTO O SUPUESTO",IF(1-K6-CONFIG!$B$8<=0,"MARGEN INVIABLE","CALCULADO"))) -> CALCULADO
A7: PIL-ARENA | B7: Calcetín Pilates Grip | C7: Calcetines Pilates | D7: Arena | E7: Unitalla | F7: ACTIVO | G7: 299 | H7: 82 | I7: 8 | J7: 9 | K7: 0.08 | L7: 5 | M7: 14 | N7: 24 | O7: 12 | P7: =IFERROR(IF(A7="","",IF(OR(COUNT(H7:J7)+COUNT(L7)<4,H7<0,I7<0,J7<0,L7<0,ABS(H7)>1000000000,ABS(I7)>1000000000,ABS(J7)>1000000000,ABS(L7)>1000000000),"",SUM(H7:J7,L7))),"") -> 104 | Q7: =IF(T7<>"OK","",G7*(1-K7)-P7) -> 171.08 | R7: =IF(OR(G7="",G7=0,Q7=""),"",Q7/G7) -> 0.57217391 | S7: =IF(OR(T7<>"OK",P7="",K7="",CONFIG!$B$8="",CONFIG!$B$8<0,CONFIG!$B$8>=1),"",IF(1-K7-CONFIG!$B$8<=0,"",ROUNDUP(ROUND(P7/(1-K7-CONFIG!$B$8),10),2))) -> 221.28 | T7: =IFERROR(IF(A7="","",IF(COUNTIF($A$6:$A$105,A7)>1,"DUPLICADO SKU",IF(OR(B7="",C7="",F7="",G7="",K7="",M7="",N7="",O7=""),"FALTA CAMPO",IF(COUNT(H7:J7)+COUNT(L7)<4,"COSTO INCOMPLETO",IF(OR(G7<=0,H7<0,I7<0,J7<0,L7<0,ABS(G7)>1000000000,ABS(H7)>1000000000,ABS(I7)>1000000000,ABS(J7)>1000000000,ABS(L7)>1000000000,ROUND(G7,2)<>G7,ROUND(H7,2)<>H7,ROUND(I7,2)<>I7,ROUND(J7,2)<>J7,ROUND(L7,2)<>L7,K7<0,K7>=1,M7<0,M7>3650,N7<=0,N7>1000000,O7<=0,O7>1000000),"REVISAR VALOR","OK"))))),"REVISAR VALOR") -> OK | U7: =IF(A7="","",IF(OR(P7="",K7="",CONFIG!$B$8=""),"FALTA COSTO O SUPUESTO",IF(1-K7-CONFIG!$B$8<=0,"MARGEN INVIABLE","CALCULADO"))) -> CALCULADO
A8: PIL-ROSA | B8: Calcetín Pilates Grip | C8: Calcetines Pilates | D8: Rosa | E8: Unitalla | F8: PRELANZAMIENTO | G8: 299 | H8: 82 | I8: 8 | J8: 9 | K8: 0.08 | L8: 5 | M8: 14 | N8: 24 | O8: 12 | P8: =IFERROR(IF(A8="","",IF(OR(COUNT(H8:J8)+COUNT(L8)<4,H8<0,I8<0,J8<0,L8<0,ABS(H8)>1000000000,ABS(I8)>1000000000,ABS(J8)>1000000000,ABS(L8)>1000000000),"",SUM(H8:J8,L8))),"") -> 104 | Q8: =IF(T8<>"OK","",G8*(1-K8)-P8) -> 171.08 | R8: =IF(OR(G8="",G8=0,Q8=""),"",Q8/G8) -> 0.57217391 | S8: =IF(OR(T8<>"OK",P8="",K8="",CONFIG!$B$8="",CONFIG!$B$8<0,CONFIG!$B$8>=1),"",IF(1-K8-CONFIG!$B$8<=0,"",ROUNDUP(ROUND(P8/(1-K8-CONFIG!$B$8),10),2))) -> 221.28 | T8: =IFERROR(IF(A8="","",IF(COUNTIF($A$6:$A$105,A8)>1,"DUPLICADO SKU",IF(OR(B8="",C8="",F8="",G8="",K8="",M8="",N8="",O8=""),"FALTA CAMPO",IF(COUNT(H8:J8)+COUNT(L8)<4,"COSTO INCOMPLETO",IF(OR(G8<=0,H8<0,I8<0,J8<0,L8<0,ABS(G8)>1000000000,ABS(H8)>1000000000,ABS(I8)>1000000000,ABS(J8)>1000000000,ABS(L8)>1000000000,ROUND(G8,2)<>G8,ROUND(H8,2)<>H8,ROUND(I8,2)<>I8,ROUND(J8,2)<>J8,ROUND(L8,2)<>L8,K8<0,K8>=1,M8<0,M8>3650,N8<=0,N8>1000000,O8<=0,O8>1000000),"REVISAR VALOR","OK"))))),"REVISAR VALOR") -> OK | U8: =IF(A8="","",IF(OR(P8="",K8="",CONFIG!$B$8=""),"FALTA COSTO O SUPUESTO",IF(1-K8-CONFIG!$B$8<=0,"MARGEN INVIABLE","CALCULADO"))) -> CALCULADO
A9: PIL-LILA | B9: Calcetín Pilates Grip | C9: Calcetines Pilates | D9: Lila | E9: Unitalla | F9: ACTIVO | G9: 299 | I9: 8 | J9: 9 | K9: 0.08 | L9: 5 | M9: 14 | N9: 24 | O9: 12 | P9: =IFERROR(IF(A9="","",IF(OR(COUNT(H9:J9)+COUNT(L9)<4,H9<0,I9<0,J9<0,L9<0,ABS(H9)>1000000000,ABS(I9)>1000000000,ABS(J9)>1000000000,ABS(L9)>1000000000),"",SUM(H9:J9,L9))),"") | Q9: =IF(T9<>"OK","",G9*(1-K9)-P9) | R9: =IF(OR(G9="",G9=0,Q9=""),"",Q9/G9) | S9: =IF(OR(T9<>"OK",P9="",K9="",CONFIG!$B$8="",CONFIG!$B$8<0,CONFIG!$B$8>=1),"",IF(1-K9-CONFIG!$B$8<=0,"",ROUNDUP(ROUND(P9/(1-K9-CONFIG!$B$8),10),2))) | T9: =IFERROR(IF(A9="","",IF(COUNTIF($A$6:$A$105,A9)>1,"DUPLICADO SKU",IF(OR(B9="",C9="",F9="",G9="",K9="",M9="",N9="",O9=""),"FALTA CAMPO",IF(COUNT(H9:J9)+COUNT(L9)<4,"COSTO INCOMPLETO",IF(OR(G9<=0,H9<0,I9<0,J9<0,L9<0,ABS(G9)>1000000000,ABS(H9)>1000000000,ABS(I9)>1000000000,ABS(J9)>1000000000,ABS(L9)>1000000000,ROUND(G9,2)<>G9,ROUND(H9,2)<>H9,ROUND(I9,2)<>I9,ROUND(J9,2)<>J9,ROUND(L9,2)<>L9,K9<0,K9>=1,M9<0,M9>3650,N9<=0,N9>1000000,O9<=0,O9>1000000),"REVISAR VALOR","OK"))))),"REVISAR VALOR") -> COSTO INCOMPLETO | U9: =IF(A9="","",IF(OR(P9="",K9="",CONFIG!$B$8=""),"FALTA COSTO O SUPUESTO",IF(1-K9-CONFIG!$B$8<=0,"MARGEN INVIABLE","CALCULADO"))) -> FALTA COSTO O SUPUESTO
A10: PIL-VERDE | B10: Calcetín Pilates Grip | C10: Calcetines Pilates | D10: Verde salvia | E10: Unitalla | F10: ACTIVO | G10: 299 | H10: 82 | I10: 8 | J10: 9 | K10: 0.08 | L10: 5 | M10: 14 | N10: 24 | O10: 12 | P10: =IFERROR(IF(A10="","",IF(OR(COUNT(H10:J10)+COUNT(L10)<4,H10<0,I10<0,J10<0,L10<0,ABS(H10)>1000000000,ABS(I10)>1000000000,ABS(J10)>1000000000,ABS(L10)>1000000000),"",SUM(H10:J10,L10))),"") -> 104 | Q10: =IF(T10<>"OK","",G10*(1-K10)-P10) -> 171.08 | R10: =IF(OR(G10="",G10=0,Q10=""),"",Q10/G10) -> 0.57217391 | S10: =IF(OR(T10<>"OK",P10="",K10="",CONFIG!$B$8="",CONFIG!$B$8<0,CONFIG!$B$8>=1),"",IF(1-K10-CONFIG!$B$8<=0,"",ROUNDUP(ROUND(P10/(1-K10-CONFIG!$B$8),10),2))) -> 221.28 | T10: =IFERROR(IF(A10="","",IF(COUNTIF($A$6:$A$105,A10)>1,"DUPLICADO SKU",IF(OR(B10="",C10="",F10="",G10="",K10="",M10="",N10="",O10=""),"FALTA CAMPO",IF(COUNT(H10:J10)+COUNT(L10)<4,"COSTO INCOMPLETO",IF(OR(G10<=0,H10<0,I10<0,J10<0,L10<0,ABS(G10)>1000000000,ABS(H10)>1000000000,ABS(I10)>1000000000,ABS(J10)>1000000000,ABS(L10)>1000000000,ROUND(G10,2)<>G10,ROUND(H10,2)<>H10,ROUND(I10,2)<>I10,ROUND(J10,2)<>J10,ROUND(L10,2)<>L10,K10<0,K10>=1,M10<0,M10>3650,N10<=0,N10>1000000,O10<=0,O10>1000000),"REVISAR VALOR","OK"))))),"REVISAR VALOR") -> OK | U10: =IF(A10="","",IF(OR(P10="",K10="",CONFIG!$B$8=""),"FALTA COSTO O SUPUESTO",IF(1-K10-CONFIG!$B$8<=0,"MARGEN INVIABLE","CALCULADO"))) -> CALCULADO
A11: PIL-AZUL | B11: Calcetín Pilates Grip | C11: Calcetines Pilates | D11: Azul noche | E11: Unitalla | F11: ACTIVO | G11: 299 | H11: 82 | I11: 8 | J11: 9 | K11: 0.08 | L11: 5 | M11: 14 | N11: 24 | O11: 12 | P11: =IFERROR(IF(A11="","",IF(OR(COUNT(H11:J11)+COUNT(L11)<4,H11<0,I11<0,J11<0,L11<0,ABS(H11)>1000000000,ABS(I11)>1000000000,ABS(J11)>1000000000,ABS(L11)>1000000000),"",SUM(H11:J11,L11))),"") -> 104 | Q11: =IF(T11<>"OK","",G11*(1-K11)-P11) -> 171.08 | R11: =IF(OR(G11="",G11=0,Q11=""),"",Q11/G11) -> 0.57217391 | S11: =IF(OR(T11<>"OK",P11="",K11="",CONFIG!$B$8="",CONFIG!$B$8<0,CONFIG!$B$8>=1),"",IF(1-K11-CONFIG!$B$8<=0,"",ROUNDUP(ROUND(P11/(1-K11-CONFIG!$B$8),10),2))) -> 221.28 | T11: =IFERROR(IF(A11="","",IF(COUNTIF($A$6:$A$105,A11)>1,"DUPLICADO SKU",IF(OR(B11="",C11="",F11="",G11="",K11="",M11="",N11="",O11=""),"FALTA CAMPO",IF(COUNT(H11:J11)+COUNT(L11)<4,"COSTO INCOMPLETO",IF(OR(G11<=0,H11<0,I11<0,J11<0,L11<0,ABS(G11)>1000000000,ABS(H11)>1000000000,ABS(I11)>1000000000,ABS(J11)>1000000000,ABS(L11)>1000000000,ROUND(G11,2)<>G11,ROUND(H11,2)<>H11,ROUND(I11,2)<>I11,ROUND(J11,2)<>J11,ROUND(L11,2)<>L11,K11<0,K11>=1,M11<0,M11>3650,N11<=0,N11>1000000,O11<=0,O11>1000000),"REVISAR VALOR","OK"))))),"REVISAR VALOR") -> OK | U11: =IF(A11="","",IF(OR(P11="",K11="",CONFIG!$B$8=""),"FALTA COSTO O SUPUESTO",IF(1-K11-CONFIG!$B$8<=0,"MARGEN INVIABLE","CALCULADO"))) -> CALCULADO
A12: PIL-VINO | B12: Calcetín Pilates Grip | C12: Calcetines Pilates | D12: Vino | E12: Unitalla | F12: ACTIVO | G12: 299 | H12: 82 | I12: 8 | J12: 9 | K12: 0.08 | L12: 5 | M12: 14 | N12: 24 | O12: 12 | P12: =IFERROR(IF(A12="","",IF(OR(COUNT(H12:J12)+COUNT(L12)<4,H12<0,I12<0,J12<0,L12<0,ABS(H12)>1000000000,ABS(I12)>1000000000,ABS(J12)>1000000000,ABS(L12)>1000000000),"",SUM(H12:J12,L12))),"") -> 104 | Q12: =IF(T12<>"OK","",G12*(1-K12)-P12) -> 171.08 | R12: =IF(OR(G12="",G12=0,Q12=""),"",Q12/G12) -> 0.57217391 | S12: =IF(OR(T12<>"OK",P12="",K12="",CONFIG!$B$8="",CONFIG!$B$8<0,CONFIG!$B$8>=1),"",IF(1-K12-CONFIG!$B$8<=0,"",ROUNDUP(ROUND(P12/(1-K12-CONFIG!$B$8),10),2))) -> 221.28 | T12: =IFERROR(IF(A12="","",IF(COUNTIF($A$6:$A$105,A12)>1,"DUPLICADO SKU",IF(OR(B12="",C12="",F12="",G12="",K12="",M12="",N12="",O12=""),"FALTA CAMPO",IF(COUNT(H12:J12)+COUNT(L12)<4,"COSTO INCOMPLETO",IF(OR(G12<=0,H12<0,I12<0,J12<0,L12<0,ABS(G12)>1000000000,ABS(H12)>1000000000,ABS(I12)>1000000000,ABS(J12)>1000000000,ABS(L12)>1000000000,ROUND(G12,2)<>G12,ROUND(H12,2)<>H12,ROUND(I12,2)<>I12,ROUND(J12,2)<>J12,ROUND(L12,2)<>L12,K12<0,K12>=1,M12<0,M12>3650,N12<=0,N12>1000000,O12<=0,O12>1000000),"REVISAR VALOR","OK"))))),"REVISAR VALOR") -> OK | U12: =IF(A12="","",IF(OR(P12="",K12="",CONFIG!$B$8=""),"FALTA COSTO O SUPUESTO",IF(1-K12-CONFIG!$B$8<=0,"MARGEN INVIABLE","CALCULADO"))) -> CALCULADO
A13: PIL-GRIS | B13: Calcetín Pilates Grip | C13: Calcetines Pilates | D13: Gris | E13: Unitalla | F13: ACTIVO | G13: 299 | H13: 82 | I13: 8 | J13: 9 | K13: 0.08 | L13: 5 | M13: 14 | N13: 12 | O13: 6 | P13: =IFERROR(IF(A13="","",IF(OR(COUNT(H13:J13)+COUNT(L13)<4,H13<0,I13<0,J13<0,L13<0,ABS(H13)>1000000000,ABS(I13)>1000000000,ABS(J13)>1000000000,ABS(L13)>1000000000),"",SUM(H13:J13,L13))),"") -> 104 | Q13: =IF(T13<>"OK","",G13*(1-K13)-P13) -> 171.08 | R13: =IF(OR(G13="",G13=0,Q13=""),"",Q13/G13) -> 0.57217391 | S13: =IF(OR(T13<>"OK",P13="",K13="",CONFIG!$B$8="",CONFIG!$B$8<0,CONFIG!$B$8>=1),"",IF(1-K13-CONFIG!$B$8<=0,"",ROUNDUP(ROUND(P13/(1-K13-CONFIG!$B$8),10),2))) -> 221.28 | T13: =IFERROR(IF(A13="","",IF(COUNTIF($A$6:$A$105,A13)>1,"DUPLICADO SKU",IF(OR(B13="",C13="",F13="",G13="",K13="",M13="",N13="",O13=""),"FALTA CAMPO",IF(COUNT(H13:J13)+COUNT(L13)<4,"COSTO INCOMPLETO",IF(OR(G13<=0,H13<0,I13<0,J13<0,L13<0,ABS(G13)>1000000000,ABS(H13)>1000000000,ABS(I13)>1000000000,ABS(J13)>1000000000,ABS(L13)>1000000000,ROUND(G13,2)<>G13,ROUND(H13,2)<>H13,ROUND(I13,2)<>I13,ROUND(J13,2)<>J13,ROUND(L13,2)<>L13,K13<0,K13>=1,M13<0,M13>3650,N13<=0,N13>1000000,O13<=0,O13>1000000),"REVISAR VALOR","OK"))))),"REVISAR VALOR") -> OK | U13: =IF(A13="","",IF(OR(P13="",K13="",CONFIG!$B$8=""),"FALTA COSTO O SUPUESTO",IF(1-K13-CONFIG!$B$8<=0,"MARGEN INVIABLE","CALCULADO"))) -> CALCULADO
A14: TOP-NEGRO-S | B14: Top deportivo Aura | C14: Ropa deportiva | D14: Negro | E14: S | F14: ACTIVO | G14: 899 | H14: 330 | I14: 20 | J14: 18 | K14: 0.08 | L14: 12 | M14: 21 | N14: 12 | O14: 6 | P14: =IFERROR(IF(A14="","",IF(OR(COUNT(H14:J14)+COUNT(L14)<4,H14<0,I14<0,J14<0,L14<0,ABS(H14)>1000000000,ABS(I14)>1000000000,ABS(J14)>1000000000,ABS(L14)>1000000000),"",SUM(H14:J14,L14))),"") -> 380 | Q14: =IF(T14<>"OK","",G14*(1-K14)-P14) -> 447.08 | R14: =IF(OR(G14="",G14=0,Q14=""),"",Q14/G14) -> 0.49730812 | S14: =IF(OR(T14<>"OK",P14="",K14="",CONFIG!$B$8="",CONFIG!$B$8<0,CONFIG!$B$8>=1),"",IF(1-K14-CONFIG!$B$8<=0,"",ROUNDUP(ROUND(P14/(1-K14-CONFIG!$B$8),10),2))) -> 808.52 | T14: =IFERROR(IF(A14="","",IF(COUNTIF($A$6:$A$105,A14)>1,"DUPLICADO SKU",IF(OR(B14="",C14="",F14="",G14="",K14="",M14="",N14="",O14=""),"FALTA CAMPO",IF(COUNT(H14:J14)+COUNT(L14)<4,"COSTO INCOMPLETO",IF(OR(G14<=0,H14<0,I14<0,J14<0,L14<0,ABS(G14)>1000000000,ABS(H14)>1000000000,ABS(I14)>1000000000,ABS(J14)>1000000000,ABS(L14)>1000000000,ROUND(G14,2)<>G14,ROUND(H14,2)<>H14,ROUND(I14,2)<>I14,ROUND(J14,2)<>J14,ROUND(L14,2)<>L14,K14<0,K14>=1,M14<0,M14>3650,N14<=0,N14>1000000,O14<=0,O14>1000000),"REVISAR VALOR","OK"))))),"REVISAR VALOR") -> OK | U14: =IF(A14="","",IF(OR(P14="",K14="",CONFIG!$B$8=""),"FALTA COSTO O SUPUESTO",IF(1-K14-CONFIG!$B$8<=0,"MARGEN INVIABLE","CALCULADO"))) -> CALCULADO
A15: LEG-NEGRO-M | B15: Legging Esencia | C15: Ropa deportiva | D15: Negro | E15: M | F15: PAUSADO | G15: 1299 | H15: 470 | I15: 25 | J15: 20 | K15: 0.08 | L15: 15 | M15: 28 | N15: 12 | O15: 6 | P15: =IFERROR(IF(A15="","",IF(OR(COUNT(H15:J15)+COUNT(L15)<4,H15<0,I15<0,J15<0,L15<0,ABS(H15)>1000000000,ABS(I15)>1000000000,ABS(J15)>1000000000,ABS(L15)>1000000000),"",SUM(H15:J15,L15))),"") -> 530 | Q15: =IF(T15<>"OK","",G15*(1-K15)-P15) -> 665.08 | R15: =IF(OR(G15="",G15=0,Q15=""),"",Q15/G15) -> 0.51199384 | S15: =IF(OR(T15<>"OK",P15="",K15="",CONFIG!$B$8="",CONFIG!$B$8<0,CONFIG!$B$8>=1),"",IF(1-K15-CONFIG!$B$8<=0,"",ROUNDUP(ROUND(P15/(1-K15-CONFIG!$B$8),10),2))) -> 1127.66 | T15: =IFERROR(IF(A15="","",IF(COUNTIF($A$6:$A$105,A15)>1,"DUPLICADO SKU",IF(OR(B15="",C15="",F15="",G15="",K15="",M15="",N15="",O15=""),"FALTA CAMPO",IF(COUNT(H15:J15)+COUNT(L15)<4,"COSTO INCOMPLETO",IF(OR(G15<=0,H15<0,I15<0,J15<0,L15<0,ABS(G15)>1000000000,ABS(H15)>1000000000,ABS(I15)>1000000000,ABS(J15)>1000000000,ABS(L15)>1000000000,ROUND(G15,2)<>G15,ROUND(H15,2)<>H15,ROUND(I15,2)<>I15,ROUND(J15,2)<>J15,ROUND(L15,2)<>L15,K15<0,K15>=1,M15<0,M15>3650,N15<=0,N15>1000000,O15<=0,O15>1000000),"REVISAR VALOR","OK"))))),"REVISAR VALOR") -> OK | U15: =IF(A15="","",IF(OR(P15="",K15="",CONFIG!$B$8=""),"FALTA COSTO O SUPUESTO",IF(1-K15-CONFIG!$B$8<=0,"MARGEN INVIABLE","CALCULADO"))) -> CALCULADO
P16: =IFERROR(IF(A16="","",IF(OR(COUNT(H16:J16)+COUNT(L16)<4,H16<0,I16<0,J16<0,L16<0,ABS(H16)>1000000000,ABS(I16)>1000000000,ABS(J16)>1000000000,ABS(L16)>1000000000),"",SUM(H16:J16,L16))),"") | Q16: =IF(T16<>"OK","",G16*(1-K16)-P16) | R16: =IF(OR(G16="",G16=0,Q16=""),"",Q16/G16) | S16: =IF(OR(T16<>"OK",P16="",K16="",CONFIG!$B$8="",CONFIG!$B$8<0,CONFIG!$B$8>=1),"",IF(1-K16-CONFIG!$B$8<=0,"",ROUNDUP(ROUND(P16/(1-K16-CONFIG!$B$8),10),2))) | T16: =IFERROR(IF(A16="","",IF(COUNTIF($A$6:$A$105,A16)>1,"DUPLICADO SKU",IF(OR(B16="",C16="",F16="",G16="",K16="",M16="",N16="",O16=""),"FALTA CAMPO",IF(COUNT(H16:J16)+COUNT(L16)<4,"COSTO INCOMPLETO",IF(OR(G16<=0,H16<0,I16<0,J16<0,L16<0,ABS(G16)>1000000000,ABS(H16)>1000000000,ABS(I16)>1000000000,ABS(J16)>1000000000,ABS(L16)>1000000000,ROUND(G16,2)<>G16,ROUND(H16,2)<>H16,ROUND(I16,2)<>I16,ROUND(J16,2)<>J16,ROUND(L16,2)<>L16,K16<0,K16>=1,M16<0,M16>3650,N16<=0,N16>1000000,O16<=0,O16>1000000),"REVISAR VALOR","OK"))))),"REVISAR VALOR") | U16: =IF(A16="","",IF(OR(P16="",K16="",CONFIG!$B$8=""),"FALTA COSTO O SUPUESTO",IF(1-K16-CONFIG!$B$8<=0,"MARGEN INVIABLE","CALCULADO")))
P17: =IFERROR(IF(A17="","",IF(OR(COUNT(H17:J17)+COUNT(L17)<4,H17<0,I17<0,J17<0,L17<0,ABS(H17)>1000000000,ABS(I17)>1000000000,ABS(J17)>1000000000,ABS(L17)>1000000000),"",SUM(H17:J17,L17))),"") | Q17: =IF(T17<>"OK","",G17*(1-K17)-P17) | R17: =IF(OR(G17="",G17=0,Q17=""),"",Q17/G17) | S17: =IF(OR(T17<>"OK",P17="",K17="",CONFIG!$B$8="",CONFIG!$B$8<0,CONFIG!$B$8>=1),"",IF(1-K17-CONFIG!$B$8<=0,"",ROUNDUP(ROUND(P17/(1-K17-CONFIG!$B$8),10),2))) | T17: =IFERROR(IF(A17="","",IF(COUNTIF($A$6:$A$105,A17)>1,"DUPLICADO SKU",IF(OR(B17="",C17="",F17="",G17="",K17="",M17="",N17="",O17=""),"FALTA CAMPO",IF(COUNT(H17:J17)+COUNT(L17)<4,"COSTO INCOMPLETO",IF(OR(G17<=0,H17<0,I17<0,J17<0,L17<0,ABS(G17)>1000000000,ABS(H17)>1000000000,ABS(I17)>1000000000,ABS(J17)>1000000000,ABS(L17)>1000000000,ROUND(G17,2)<>G17,ROUND(H17,2)<>H17,ROUND(I17,2)<>I17,ROUND(J17,2)<>J17,ROUND(L17,2)<>L17,K17<0,K17>=1,M17<0,M17>3650,N17<=0,N17>1000000,O17<=0,O17>1000000),"REVISAR VALOR","OK"))))),"REVISAR VALOR") | U17: =IF(A17="","",IF(OR(P17="",K17="",CONFIG!$B$8=""),"FALTA COSTO O SUPUESTO",IF(1-K17-CONFIG!$B$8<=0,"MARGEN INVIABLE","CALCULADO")))
P18: =IFERROR(IF(A18="","",IF(OR(COUNT(H18:J18)+COUNT(L18)<4,H18<0,I18<0,J18<0,L18<0,ABS(H18)>1000000000,ABS(I18)>1000000000,ABS(J18)>1000000000,ABS(L18)>1000000000),"",SUM(H18:J18,L18))),"") | Q18: =IF(T18<>"OK","",G18*(1-K18)-P18) | R18: =IF(OR(G18="",G18=0,Q18=""),"",Q18/G18) | S18: =IF(OR(T18<>"OK",P18="",K18="",CONFIG!$B$8="",CONFIG!$B$8<0,CONFIG!$B$8>=1),"",IF(1-K18-CONFIG!$B$8<=0,"",ROUNDUP(ROUND(P18/(1-K18-CONFIG!$B$8),10),2))) | T18: =IFERROR(IF(A18="","",IF(COUNTIF($A$6:$A$105,A18)>1,"DUPLICADO SKU",IF(OR(B18="",C18="",F18="",G18="",K18="",M18="",N18="",O18=""),"FALTA CAMPO",IF(COUNT(H18:J18)+COUNT(L18)<4,"COSTO INCOMPLETO",IF(OR(G18<=0,H18<0,I18<0,J18<0,L18<0,ABS(G18)>1000000000,ABS(H18)>1000000000,ABS(I18)>1000000000,ABS(J18)>1000000000,ABS(L18)>1000000000,ROUND(G18,2)<>G18,ROUND(H18,2)<>H18,ROUND(I18,2)<>I18,ROUND(J18,2)<>J18,ROUND(L18,2)<>L18,K18<0,K18>=1,M18<0,M18>3650,N18<=0,N18>1000000,O18<=0,O18>1000000),"REVISAR VALOR","OK"))))),"REVISAR VALOR") | U18: =IF(A18="","",IF(OR(P18="",K18="",CONFIG!$B$8=""),"FALTA COSTO O SUPUESTO",IF(1-K18-CONFIG!$B$8<=0,"MARGEN INVIABLE","CALCULADO")))
P19: =IFERROR(IF(A19="","",IF(OR(COUNT(H19:J19)+COUNT(L19)<4,H19<0,I19<0,J19<0,L19<0,ABS(H19)>1000000000,ABS(I19)>1000000000,ABS(J19)>1000000000,ABS(L19)>1000000000),"",SUM(H19:J19,L19))),"") | Q19: =IF(T19<>"OK","",G19*(1-K19)-P19) | R19: =IF(OR(G19="",G19=0,Q19=""),"",Q19/G19) | S19: =IF(OR(T19<>"OK",P19="",K19="",CONFIG!$B$8="",CONFIG!$B$8<0,CONFIG!$B$8>=1),"",IF(1-K19-CONFIG!$B$8<=0,"",ROUNDUP(ROUND(P19/(1-K19-CONFIG!$B$8),10),2))) | T19: =IFERROR(IF(A19="","",IF(COUNTIF($A$6:$A$105,A19)>1,"DUPLICADO SKU",IF(OR(B19="",C19="",F19="",G19="",K19="",M19="",N19="",O19=""),"FALTA CAMPO",IF(COUNT(H19:J19)+COUNT(L19)<4,"COSTO INCOMPLETO",IF(OR(G19<=0,H19<0,I19<0,J19<0,L19<0,ABS(G19)>1000000000,ABS(H19)>1000000000,ABS(I19)>1000000000,ABS(J19)>1000000000,ABS(L19)>1000000000,ROUND(G19,2)<>G19,ROUND(H19,2)<>H19,ROUND(I19,2)<>I19,ROUND(J19,2)<>J19,ROUND(L19,2)<>L19,K19<0,K19>=1,M19<0,M19>3650,N19<=0,N19>1000000,O19<=0,O19>1000000),"REVISAR VALOR","OK"))))),"REVISAR VALOR") | U19: =IF(A19="","",IF(OR(P19="",K19="",CONFIG!$B$8=""),"FALTA COSTO O SUPUESTO",IF(1-K19-CONFIG!$B$8<=0,"MARGEN INVIABLE","CALCULADO")))
P20: =IFERROR(IF(A20="","",IF(OR(COUNT(H20:J20)+COUNT(L20)<4,H20<0,I20<0,J20<0,L20<0,ABS(H20)>1000000000,ABS(I20)>1000000000,ABS(J20)>1000000000,ABS(L20)>1000000000),"",SUM(H20:J20,L20))),"") | Q20: =IF(T20<>"OK","",G20*(1-K20)-P20) | R20: =IF(OR(G20="",G20=0,Q20=""),"",Q20/G20) | S20: =IF(OR(T20<>"OK",P20="",K20="",CONFIG!$B$8="",CONFIG!$B$8<0,CONFIG!$B$8>=1),"",IF(1-K20-CONFIG!$B$8<=0,"",ROUNDUP(ROUND(P20/(1-K20-CONFIG!$B$8),10),2))) | T20: =IFERROR(IF(A20="","",IF(COUNTIF($A$6:$A$105,A20)>1,"DUPLICADO SKU",IF(OR(B20="",C20="",F20="",G20="",K20="",M20="",N20="",O20=""),"FALTA CAMPO",IF(COUNT(H20:J20)+COUNT(L20)<4,"COSTO INCOMPLETO",IF(OR(G20<=0,H20<0,I20<0,J20<0,L20<0,ABS(G20)>1000000000,ABS(H20)>1000000000,ABS(I20)>1000000000,ABS(J20)>1000000000,ABS(L20)>1000000000,ROUND(G20,2)<>G20,ROUND(H20,2)<>H20,ROUND(I20,2)<>I20,ROUND(J20,2)<>J20,ROUND(L20,2)<>L20,K20<0,K20>=1,M20<0,M20>3650,N20<=0,N20>1000000,O20<=0,O20>1000000),"REVISAR VALOR","OK"))))),"REVISAR VALOR") | U20: =IF(A20="","",IF(OR(P20="",K20="",CONFIG!$B$8=""),"FALTA COSTO O SUPUESTO",IF(1-K20-CONFIG!$B$8<=0,"MARGEN INVIABLE","CALCULADO")))
P21: =IFERROR(IF(A21="","",IF(OR(COUNT(H21:J21)+COUNT(L21)<4,H21<0,I21<0,J21<0,L21<0,ABS(H21)>1000000000,ABS(I21)>1000000000,ABS(J21)>1000000000,ABS(L21)>1000000000),"",SUM(H21:J21,L21))),"") | Q21: =IF(T21<>"OK","",G21*(1-K21)-P21) | R21: =IF(OR(G21="",G21=0,Q21=""),"",Q21/G21) | S21: =IF(OR(T21<>"OK",P21="",K21="",CONFIG!$B$8="",CONFIG!$B$8<0,CONFIG!$B$8>=1),"",IF(1-K21-CONFIG!$B$8<=0,"",ROUNDUP(ROUND(P21/(1-K21-CONFIG!$B$8),10),2))) | T21: =IFERROR(IF(A21="","",IF(COUNTIF($A$6:$A$105,A21)>1,"DUPLICADO SKU",IF(OR(B21="",C21="",F21="",G21="",K21="",M21="",N21="",O21=""),"FALTA CAMPO",IF(COUNT(H21:J21)+COUNT(L21)<4,"COSTO INCOMPLETO",IF(OR(G21<=0,H21<0,I21<0,J21<0,L21<0,ABS(G21)>1000000000,ABS(H21)>1000000000,ABS(I21)>1000000000,ABS(J21)>1000000000,ABS(L21)>1000000000,ROUND(G21,2)<>G21,ROUND(H21,2)<>H21,ROUND(I21,2)<>I21,ROUND(J21,2)<>J21,ROUND(L21,2)<>L21,K21<0,K21>=1,M21<0,M21>3650,N21<=0,N21>1000000,O21<=0,O21>1000000),"REVISAR VALOR","OK"))))),"REVISAR VALOR") | U21: =IF(A21="","",IF(OR(P21="",K21="",CONFIG!$B$8=""),"FALTA COSTO O SUPUESTO",IF(1-K21-CONFIG!$B$8<=0,"MARGEN INVIABLE","CALCULADO")))
P22: =IFERROR(IF(A22="","",IF(OR(COUNT(H22:J22)+COUNT(L22)<4,H22<0,I22<0,J22<0,L22<0,ABS(H22)>1000000000,ABS(I22)>1000000000,ABS(J22)>1000000000,ABS(L22)>1000000000),"",SUM(H22:J22,L22))),"") | Q22: =IF(T22<>"OK","",G22*(1-K22)-P22) | R22: =IF(OR(G22="",G22=0,Q22=""),"",Q22/G22) | S22: =IF(OR(T22<>"OK",P22="",K22="",CONFIG!$B$8="",CONFIG!$B$8<0,CONFIG!$B$8>=1),"",IF(1-K22-CONFIG!$B$8<=0,"",ROUNDUP(ROUND(P22/(1-K22-CONFIG!$B$8),10),2))) | T22: =IFERROR(IF(A22="","",IF(COUNTIF($A$6:$A$105,A22)>1,"DUPLICADO SKU",IF(OR(B22="",C22="",F22="",G22="",K22="",M22="",N22="",O22=""),"FALTA CAMPO",IF(COUNT(H22:J22)+COUNT(L22)<4,"COSTO INCOMPLETO",IF(OR(G22<=0,H22<0,I22<0,J22<0,L22<0,ABS(G22)>1000000000,ABS(H22)>1000000000,ABS(I22)>1000000000,ABS(J22)>1000000000,ABS(L22)>1000000000,ROUND(G22,2)<>G22,ROUND(H22,2)<>H22,ROUND(I22,2)<>I22,ROUND(J22,2)<>J22,ROUND(L22,2)<>L22,K22<0,K22>=1,M22<0,M22>3650,N22<=0,N22>1000000,O22<=0,O22>1000000),"REVISAR VALOR","OK"))))),"REVISAR VALOR") | U22: =IF(A22="","",IF(OR(P22="",K22="",CONFIG!$B$8=""),"FALTA COSTO O SUPUESTO",IF(1-K22-CONFIG!$B$8<=0,"MARGEN INVIABLE","CALCULADO")))
P23: =IFERROR(IF(A23="","",IF(OR(COUNT(H23:J23)+COUNT(L23)<4,H23<0,I23<0,J23<0,L23<0,ABS(H23)>1000000000,ABS(I23)>1000000000,ABS(J23)>1000000000,ABS(L23)>1000000000),"",SUM(H23:J23,L23))),"") | Q23: =IF(T23<>"OK","",G23*(1-K23)-P23) | R23: =IF(OR(G23="",G23=0,Q23=""),"",Q23/G23) | S23: =IF(OR(T23<>"OK",P23="",K23="",CONFIG!$B$8="",CONFIG!$B$8<0,CONFIG!$B$8>=1),"",IF(1-K23-CONFIG!$B$8<=0,"",ROUNDUP(ROUND(P23/(1-K23-CONFIG!$B$8),10),2))) | T23: =IFERROR(IF(A23="","",IF(COUNTIF($A$6:$A$105,A23)>1,"DUPLICADO SKU",IF(OR(B23="",C23="",F23="",G23="",K23="",M23="",N23="",O23=""),"FALTA CAMPO",IF(COUNT(H23:J23)+COUNT(L23)<4,"COSTO INCOMPLETO",IF(OR(G23<=0,H23<0,I23<0,J23<0,L23<0,ABS(G23)>1000000000,ABS(H23)>1000000000,ABS(I23)>1000000000,ABS(J23)>1000000000,ABS(L23)>1000000000,ROUND(G23,2)<>G23,ROUND(H23,2)<>H23,ROUND(I23,2)<>I23,ROUND(J23,2)<>J23,ROUND(L23,2)<>L23,K23<0,K23>=1,M23<0,M23>3650,N23<=0,N23>1000000,O23<=0,O23>1000000),"REVISAR VALOR","OK"))))),"REVISAR VALOR") | U23: =IF(A23="","",IF(OR(P23="",K23="",CONFIG!$B$8=""),"FALTA COSTO O SUPUESTO",IF(1-K23-CONFIG!$B$8<=0,"MARGEN INVIABLE","CALCULADO")))
P24: =IFERROR(IF(A24="","",IF(OR(COUNT(H24:J24)+COUNT(L24)<4,H24<0,I24<0,J24<0,L24<0,ABS(H24)>1000000000,ABS(I24)>1000000000,ABS(J24)>1000000000,ABS(L24)>1000000000),"",SUM(H24:J24,L24))),"") | Q24: =IF(T24<>"OK","",G24*(1-K24)-P24) | R24: =IF(OR(G24="",G24=0,Q24=""),"",Q24/G24) | S24: =IF(OR(T24<>"OK",P24="",K24="",CONFIG!$B$8="",CONFIG!$B$8<0,CONFIG!$B$8>=1),"",IF(1-K24-CONFIG!$B$8<=0,"",ROUNDUP(ROUND(P24/(1-K24-CONFIG!$B$8),10),2))) | T24: =IFERROR(IF(A24="","",IF(COUNTIF($A$6:$A$105,A24)>1,"DUPLICADO SKU",IF(OR(B24="",C24="",F24="",G24="",K24="",M24="",N24="",O24=""),"FALTA CAMPO",IF(COUNT(H24:J24)+COUNT(L24)<4,"COSTO INCOMPLETO",IF(OR(G24<=0,H24<0,I24<0,J24<0,L24<0,ABS(G24)>1000000000,ABS(H24)>1000000000,ABS(I24)>1000000000,ABS(J24)>1000000000,ABS(L24)>1000000000,ROUND(G24,2)<>G24,ROUND(H24,2)<>H24,ROUND(I24,2)<>I24,ROUND(J24,2)<>J24,ROUND(L24,2)<>L24,K24<0,K24>=1,M24<0,M24>3650,N24<=0,N24>1000000,O24<=0,O24>1000000),"REVISAR VALOR","OK"))))),"REVISAR VALOR") | U24: =IF(A24="","",IF(OR(P24="",K24="",CONFIG!$B$8=""),"FALTA COSTO O SUPUESTO",IF(1-K24-CONFIG!$B$8<=0,"MARGEN INVIABLE","CALCULADO")))
P25: =IFERROR(IF(A25="","",IF(OR(COUNT(H25:J25)+COUNT(L25)<4,H25<0,I25<0,J25<0,L25<0,ABS(H25)>1000000000,ABS(I25)>1000000000,ABS(J25)>1000000000,ABS(L25)>1000000000),"",SUM(H25:J25,L25))),"") | Q25: =IF(T25<>"OK","",G25*(1-K25)-P25) | R25: =IF(OR(G25="",G25=0,Q25=""),"",Q25/G25) | S25: =IF(OR(T25<>"OK",P25="",K25="",CONFIG!$B$8="",CONFIG!$B$8<0,CONFIG!$B$8>=1),"",IF(1-K25-CONFIG!$B$8<=0,"",ROUNDUP(ROUND(P25/(1-K25-CONFIG!$B$8),10),2))) | T25: =IFERROR(IF(A25="","",IF(COUNTIF($A$6:$A$105,A25)>1,"DUPLICADO SKU",IF(OR(B25="",C25="",F25="",G25="",K25="",M25="",N25="",O25=""),"FALTA CAMPO",IF(COUNT(H25:J25)+COUNT(L25)<4,"COSTO INCOMPLETO",IF(OR(G25<=0,H25<0,I25<0,J25<0,L25<0,ABS(G25)>1000000000,ABS(H25)>1000000000,ABS(I25)>1000000000,ABS(J25)>1000000000,ABS(L25)>1000000000,ROUND(G25,2)<>G25,ROUND(H25,2)<>H25,ROUND(I25,2)<>I25,ROUND(J25,2)<>J25,ROUND(L25,2)<>L25,K25<0,K25>=1,M25<0,M25>3650,N25<=0,N25>1000000,O25<=0,O25>1000000),"REVISAR VALOR","OK"))))),"REVISAR VALOR") | U25: =IF(A25="","",IF(OR(P25="",K25="",CONFIG!$B$8=""),"FALTA COSTO O SUPUESTO",IF(1-K25-CONFIG!$B$8<=0,"MARGEN INVIABLE","CALCULADO")))
P26: =IFERROR(IF(A26="","",IF(OR(COUNT(H26:J26)+COUNT(L26)<4,H26<0,I26<0,J26<0,L26<0,ABS(H26)>1000000000,ABS(I26)>1000000000,ABS(J26)>1000000000,ABS(L26)>1000000000),"",SUM(H26:J26,L26))),"") | Q26: =IF(T26<>"OK","",G26*(1-K26)-P26) | R26: =IF(OR(G26="",G26=0,Q26=""),"",Q26/G26) | S26: =IF(OR(T26<>"OK",P26="",K26="",CONFIG!$B$8="",CONFIG!$B$8<0,CONFIG!$B$8>=1),"",IF(1-K26-CONFIG!$B$8<=0,"",ROUNDUP(ROUND(P26/(1-K26-CONFIG!$B$8),10),2))) | T26: =IFERROR(IF(A26="","",IF(COUNTIF($A$6:$A$105,A26)>1,"DUPLICADO SKU",IF(OR(B26="",C26="",F26="",G26="",K26="",M26="",N26="",O26=""),"FALTA CAMPO",IF(COUNT(H26:J26)+COUNT(L26)<4,"COSTO INCOMPLETO",IF(OR(G26<=0,H26<0,I26<0,J26<0,L26<0,ABS(G26)>1000000000,ABS(H26)>1000000000,ABS(I26)>1000000000,ABS(J26)>1000000000,ABS(L26)>1000000000,ROUND(G26,2)<>G26,ROUND(H26,2)<>H26,ROUND(I26,2)<>I26,ROUND(J26,2)<>J26,ROUND(L26,2)<>L26,K26<0,K26>=1,M26<0,M26>3650,N26<=0,N26>1000000,O26<=0,O26>1000000),"REVISAR VALOR","OK"))))),"REVISAR VALOR") | U26: =IF(A26="","",IF(OR(P26="",K26="",CONFIG!$B$8=""),"FALTA COSTO O SUPUESTO",IF(1-K26-CONFIG!$B$8<=0,"MARGEN INVIABLE","CALCULADO")))
P27: =IFERROR(IF(A27="","",IF(OR(COUNT(H27:J27)+COUNT(L27)<4,H27<0,I27<0,J27<0,L27<0,ABS(H27)>1000000000,ABS(I27)>1000000000,ABS(J27)>1000000000,ABS(L27)>1000000000),"",SUM(H27:J27,L27))),"") | Q27: =IF(T27<>"OK","",G27*(1-K27)-P27) | R27: =IF(OR(G27="",G27=0,Q27=""),"",Q27/G27) | S27: =IF(OR(T27<>"OK",P27="",K27="",CONFIG!$B$8="",CONFIG!$B$8<0,CONFIG!$B$8>=1),"",IF(1-K27-CONFIG!$B$8<=0,"",ROUNDUP(ROUND(P27/(1-K27-CONFIG!$B$8),10),2))) | T27: =IFERROR(IF(A27="","",IF(COUNTIF($A$6:$A$105,A27)>1,"DUPLICADO SKU",IF(OR(B27="",C27="",F27="",G27="",K27="",M27="",N27="",O27=""),"FALTA CAMPO",IF(COUNT(H27:J27)+COUNT(L27)<4,"COSTO INCOMPLETO",IF(OR(G27<=0,H27<0,I27<0,J27<0,L27<0,ABS(G27)>1000000000,ABS(H27)>1000000000,ABS(I27)>1000000000,ABS(J27)>1000000000,ABS(L27)>1000000000,ROUND(G27,2)<>G27,ROUND(H27,2)<>H27,ROUND(I27,2)<>I27,ROUND(J27,2)<>J27,ROUND(L27,2)<>L27,K27<0,K27>=1,M27<0,M27>3650,N27<=0,N27>1000000,O27<=0,O27>1000000),"REVISAR VALOR","OK"))))),"REVISAR VALOR") | U27: =IF(A27="","",IF(OR(P27="",K27="",CONFIG!$B$8=""),"FALTA COSTO O SUPUESTO",IF(1-K27-CONFIG!$B$8<=0,"MARGEN INVIABLE","CALCULADO")))
... P105: =IFERROR(IF(A105="","",IF(OR(COUNT(H105:J105)+COUNT(L105)<4,H105<0,I105<0,J105<0,L105<0,ABS(H105)>1000000000,ABS(I105)>1000000000,ABS(J105)>1000000000,ABS(L105)>1000000000),"",SUM(H105:J105,L105))),"") | Q105: =IF(T105<>"OK","",G105*(1-K105)-P105) | R105: =IF(OR(G105="",G105=0,Q105=""),"",Q105/G105) | S105: =IF(OR(T105<>"OK",P105="",K105="",CONFIG!$B$8="",CONFIG!$B$8<0,CONFIG!$B$8>=1),"",IF(1-K105-CONFIG!$B$8<=0,"",ROUNDUP(ROUND(P105/(1-K105-CONFIG!$B$8),10),2))) | T105: =IFERROR(IF(A105="","",IF(COUNTIF($A$6:$A$105,A105)>1,"DUPLICADO SKU",IF(OR(B105="",C105="",F105="",G105="",K105="",M105="",N105="",O105=""),"FALTA CAMPO",IF(COUNT(H105:J105)+COUNT(L105)<4,"COSTO INCOMPLETO",IF(OR(G105<=0,H105<0,I105<0,J105<0,L105<0,ABS(G105)>1000000000,ABS(H105)>1000000000,ABS(I105)>1000000000,ABS(J105)>1000000000,ABS(L105)>1000000000,ROUND(G105,2)<>G105,ROUND(H105,2)<>H105,ROUND(I105,2)<>I105,ROUND(J105,2)<>J105,ROUND(L105,2)<>L105,K105<0,K105>=1,M105<0,M105>3650,N105<=0,N105>1000000,O105<=0,O105>1000000),"REVISAR VALOR","OK"))))),"REVISAR VALOR") | U105: =IF(A105="","",IF(OR(P105="",K105="",CONFIG!$B$8=""),"FALTA COSTO O SUPUESTO",IF(1-K105-CONFIG!$B$8<=0,"MARGEN INVIABLE","CALCULADO")))

Sheet VENTAS
A1: VENTAS DIARIAS AGREGADAS
A2: Azul = captura editable · Verde = vínculo entre hojas · Negro = cálculo. Blanco significa desconocido; cero es un valor explícito. Un renglón por fecha y SKU; devolución, reingreso físico y reembolso de caja son hechos distintos.
A5: Fecha | B5: SKU | C5: Unidades entregadas | D5: Unidades devueltas | E5: Unidades reingresadas | F5: Ingreso neto (MXN pesos) | G5: Costo variable real (MXN pesos, opcional) | H5: Referencia no personal | I5: Calidad fila
A6: 46259 | B6: PIL-NEGRO | C6: 3 | D6: 1 | E6: 1 | F6: 598 | G6: 208 | H6: SYNTH-20260825 | I6: =IFERROR(IF(COUNTA(A6:H6)=0,"",IF(OR(A6="",B6="",C6="",D6="",E6="",F6=""),"FALTA CAMPO",IF(COUNTIFS($A$6:$A$1005,A6,$B$6:$B$1005,B6)>1,"DUPLICADO FECHA-SKU",IF(COUNTIF(CATALOGO!$A$6:$A$105,B6)<>1,"SKU NO VALIDO",IF(OR(A6<DATE(1900,1,1),A6>DATE(2100,12,31),A6>CONFIG!$B$5,C6<0,C6>1000000,D6<0,D6>1000000,E6<0,E6>1000000,E6>D6,ABS(F6)>1000000000,ABS(G6)>1000000000,ROUND(F6,2)<>F6,AND(G6<>"",ROUND(G6,2)<>G6)),"REVISAR VALOR","OK"))))),"REVISAR VALOR") -> OK
A7: 46260 | B7: PIL-NEGRO | C7: 3 | D7: 1 | E7: 1 | F7: 598 | G7: 208 | H7: SYNTH-20260826 | I7: =IFERROR(IF(COUNTA(A7:H7)=0,"",IF(OR(A7="",B7="",C7="",D7="",E7="",F7=""),"FALTA CAMPO",IF(COUNTIFS($A$6:$A$1005,A7,$B$6:$B$1005,B7)>1,"DUPLICADO FECHA-SKU",IF(COUNTIF(CATALOGO!$A$6:$A$105,B7)<>1,"SKU NO VALIDO",IF(OR(A7<DATE(1900,1,1),A7>DATE(2100,12,31),A7>CONFIG!$B$5,C7<0,C7>1000000,D7<0,D7>1000000,E7<0,E7>1000000,E7>D7,ABS(F7)>1000000000,ABS(G7)>1000000000,ROUND(F7,2)<>F7,AND(G7<>"",ROUND(G7,2)<>G7)),"REVISAR VALOR","OK"))))),"REVISAR VALOR") -> OK
A8: 46261 | B8: PIL-NEGRO | C8: 3 | D8: 1 | E8: 1 | F8: 598 | G8: 208 | H8: SYNTH-20260827 | I8: =IFERROR(IF(COUNTA(A8:H8)=0,"",IF(OR(A8="",B8="",C8="",D8="",E8="",F8=""),"FALTA CAMPO",IF(COUNTIFS($A$6:$A$1005,A8,$B$6:$B$1005,B8)>1,"DUPLICADO FECHA-SKU",IF(COUNTIF(CATALOGO!$A$6:$A$105,B8)<>1,"SKU NO VALIDO",IF(OR(A8<DATE(1900,1,1),A8>DATE(2100,12,31),A8>CONFIG!$B$5,C8<0,C8>1000000,D8<0,D8>1000000,E8<0,E8>1000000,E8>D8,ABS(F8)>1000000000,ABS(G8)>1000000000,ROUND(F8,2)<>F8,AND(G8<>"",ROUND(G8,2)<>G8)),"REVISAR VALOR","OK"))))),"REVISAR VALOR") -> OK
A9: 46262 | B9: PIL-NEGRO | C9: 3 | D9: 1 | E9: 1 | F9: 598 | G9: 208 | H9: SYNTH-20260828 | I9: =IFERROR(IF(COUNTA(A9:H9)=0,"",IF(OR(A9="",B9="",C9="",D9="",E9="",F9=""),"FALTA CAMPO",IF(COUNTIFS($A$6:$A$1005,A9,$B$6:$B$1005,B9)>1,"DUPLICADO FECHA-SKU",IF(COUNTIF(CATALOGO!$A$6:$A$105,B9)<>1,"SKU NO VALIDO",IF(OR(A9<DATE(1900,1,1),A9>DATE(2100,12,31),A9>CONFIG!$B$5,C9<0,C9>1000000,D9<0,D9>1000000,E9<0,E9>1000000,E9>D9,ABS(F9)>1000000000,ABS(G9)>1000000000,ROUND(F9,2)<>F9,AND(G9<>"",ROUND(G9,2)<>G9)),"REVISAR VALOR","OK"))))),"REVISAR VALOR") -> OK
A10: 46263 | B10: PIL-NEGRO | C10: 2 | D10: 1 | E10: 0 | F10: 299 | G10: 208 | H10: SYNTH-20260829 | I10: =IFERROR(IF(COUNTA(A10:H10)=0,"",IF(OR(A10="",B10="",C10="",D10="",E10="",F10=""),"FALTA CAMPO",IF(COUNTIFS($A$6:$A$1005,A10,$B$6:$B$1005,B10)>1,"DUPLICADO FECHA-SKU",IF(COUNTIF(CATALOGO!$A$6:$A$105,B10)<>1,"SKU NO VALIDO",IF(OR(A10<DATE(1900,1,1),A10>DATE(2100,12,31),A10>CONFIG!$B$5,C10<0,C10>1000000,D10<0,D10>1000000,E10<0,E10>1000000,E10>D10,ABS(F10)>1000000000,ABS(G10)>1000000000,ROUND(F10,2)<>F10,AND(G10<>"",ROUND(G10,2)<>G10)),"REVISAR VALOR","OK"))))),"REVISAR VALOR") -> OK
A11: 46264 | B11: PIL-NEGRO | C11: 2 | D11: 0 | E11: 0 | F11: 598 | G11: 208 | H11: SYNTH-20260830 | I11: =IFERROR(IF(COUNTA(A11:H11)=0,"",IF(OR(A11="",B11="",C11="",D11="",E11="",F11=""),"FALTA CAMPO",IF(COUNTIFS($A$6:$A$1005,A11,$B$6:$B$1005,B11)>1,"DUPLICADO FECHA-SKU",IF(COUNTIF(CATALOGO!$A$6:$A$105,B11)<>1,"SKU NO VALIDO",IF(OR(A11<DATE(1900,1,1),A11>DATE(2100,12,31),A11>CONFIG!$B$5,C11<0,C11>1000000,D11<0,D11>1000000,E11<0,E11>1000000,E11>D11,ABS(F11)>1000000000,ABS(G11)>1000000000,ROUND(F11,2)<>F11,AND(G11<>"",ROUND(G11,2)<>G11)),"REVISAR VALOR","OK"))))),"REVISAR VALOR") -> OK
A12: 46265 | B12: PIL-NEGRO | C12: 2 | D12: 0 | E12: 0 | F12: 598 | G12: 208 | H12: SYNTH-20260831 | I12: =IFERROR(IF(COUNTA(A12:H12)=0,"",IF(OR(A12="",B12="",C12="",D12="",E12="",F12=""),"FALTA CAMPO",IF(COUNTIFS($A$6:$A$1005,A12,$B$6:$B$1005,B12)>1,"DUPLICADO FECHA-SKU",IF(COUNTIF(CATALOGO!$A$6:$A$105,B12)<>1,"SKU NO VALIDO",IF(OR(A12<DATE(1900,1,1),A12>DATE(2100,12,31),A12>CONFIG!$B$5,C12<0,C12>1000000,D12<0,D12>1000000,E12<0,E12>1000000,E12>D12,ABS(F12)>1000000000,ABS(G12)>1000000000,ROUND(F12,2)<>F12,AND(G12<>"",ROUND(G12,2)<>G12)),"REVISAR VALOR","OK"))))),"REVISAR VALOR") -> OK
A13: 46266 | B13: PIL-NEGRO | C13: 2 | D13: 0 | E13: 0 | F13: 598 | G13: 208 | H13: SYNTH-20260901 | I13: =IFERROR(IF(COUNTA(A13:H13)=0,"",IF(OR(A13="",B13="",C13="",D13="",E13="",F13=""),"FALTA CAMPO",IF(COUNTIFS($A$6:$A$1005,A13,$B$6:$B$1005,B13)>1,"DUPLICADO FECHA-SKU",IF(COUNTIF(CATALOGO!$A$6:$A$105,B13)<>1,"SKU NO VALIDO",IF(OR(A13<DATE(1900,1,1),A13>DATE(2100,12,31),A13>CONFIG!$B$5,C13<0,C13>1000000,D13<0,D13>1000000,E13<0,E13>1000000,E13>D13,ABS(F13)>1000000000,ABS(G13)>1000000000,ROUND(F13,2)<>F13,AND(G13<>"",ROUND(G13,2)<>G13)),"REVISAR VALOR","OK"))))),"REVISAR VALOR") -> OK
A14: 46267 | B14: PIL-NEGRO | C14: 2 | D14: 0 | E14: 0 | F14: 598 | G14: 208 | H14: SYNTH-20260902 | I14: =IFERROR(IF(COUNTA(A14:H14)=0,"",IF(OR(A14="",B14="",C14="",D14="",E14="",F14=""),"FALTA CAMPO",IF(COUNTIFS($A$6:$A$1005,A14,$B$6:$B$1005,B14)>1,"DUPLICADO FECHA-SKU",IF(COUNTIF(CATALOGO!$A$6:$A$105,B14)<>1,"SKU NO VALIDO",IF(OR(A14<DATE(1900,1,1),A14>DATE(2100,12,31),A14>CONFIG!$B$5,C14<0,C14>1000000,D14<0,D14>1000000,E14<0,E14>1000000,E14>D14,ABS(F14)>1000000000,ABS(G14)>1000000000,ROUND(F14,2)<>F14,AND(G14<>"",ROUND(G14,2)<>G14)),"REVISAR VALOR","OK"))))),"REVISAR VALOR") -> OK
A15: 46268 | B15: PIL-NEGRO | C15: 2 | D15: 0 | E15: 0 | F15: 598 | G15: 208 | H15: SYNTH-20260903 | I15: =IFERROR(IF(COUNTA(A15:H15)=0,"",IF(OR(A15="",B15="",C15="",D15="",E15="",F15=""),"FALTA CAMPO",IF(COUNTIFS($A$6:$A$1005,A15,$B$6:$B$1005,B15)>1,"DUPLICADO FECHA-SKU",IF(COUNTIF(CATALOGO!$A$6:$A$105,B15)<>1,"SKU NO VALIDO",IF(OR(A15<DATE(1900,1,1),A15>DATE(2100,12,31),A15>CONFIG!$B$5,C15<0,C15>1000000,D15<0,D15>1000000,E15<0,E15>1000000,E15>D15,ABS(F15)>1000000000,ABS(G15)>1000000000,ROUND(F15,2)<>F15,AND(G15<>"",ROUND(G15,2)<>G15)),"REVISAR VALOR","OK"))))),"REVISAR VALOR") -> OK
A16: 46269 | B16: PIL-NEGRO | C16: 2 | D16: 0 | E16: 0 | F16: 598 | G16: 208 | H16: SYNTH-20260904 | I16: =IFERROR(IF(COUNTA(A16:H16)=0,"",IF(OR(A16="",B16="",C16="",D16="",E16="",F16=""),"FALTA CAMPO",IF(COUNTIFS($A$6:$A$1005,A16,$B$6:$B$1005,B16)>1,"DUPLICADO FECHA-SKU",IF(COUNTIF(CATALOGO!$A$6:$A$105,B16)<>1,"SKU NO VALIDO",IF(OR(A16<DATE(1900,1,1),A16>DATE(2100,12,31),A16>CONFIG!$B$5,C16<0,C16>1000000,D16<0,D16>1000000,E16<0,E16>1000000,E16>D16,ABS(F16)>1000000000,ABS(G16)>1000000000,ROUND(F16,2)<>F16,AND(G16<>"",ROUND(G16,2)<>G16)),"REVISAR VALOR","OK"))))),"REVISAR VALOR") -> OK
A17: 46270 | B17: PIL-NEGRO | C17: 2 | D17: 0 | E17: 0 | F17: 598 | G17: 208 | H17: SYNTH-20260905 | I17: =IFERROR(IF(COUNTA(A17:H17)=0,"",IF(OR(A17="",B17="",C17="",D17="",E17="",F17=""),"FALTA CAMPO",IF(COUNTIFS($A$6:$A$1005,A17,$B$6:$B$1005,B17)>1,"DUPLICADO FECHA-SKU",IF(COUNTIF(CATALOGO!$A$6:$A$105,B17)<>1,"SKU NO VALIDO",IF(OR(A17<DATE(1900,1,1),A17>DATE(2100,12,31),A17>CONFIG!$B$5,C17<0,C17>1000000,D17<0,D17>1000000,E17<0,E17>1000000,E17>D17,ABS(F17)>1000000000,ABS(G17)>1000000000,ROUND(F17,2)<>F17,AND(G17<>"",ROUND(G17,2)<>G17)),"REVISAR VALOR","OK"))))),"REVISAR VALOR") -> OK
... A89: 46286 | B89: PIL-ROSA | C89: 0 | D89: 0 | E89: 0 | F89: 0 | G89: 0 | H89: SYNTH-20260921 | I89: =IFERROR(IF(COUNTA(A89:H89)=0,"",IF(OR(A89="",B89="",C89="",D89="",E89="",F89=""),"FALTA CAMPO",IF(COUNTIFS($A$6:$A$1005,A89,$B$6:$B$1005,B89)>1,"DUPLICADO FECHA-SKU",IF(COUNTIF(CATALOGO!$A$6:$A$105,B89)<>1,"SKU NO VALIDO",IF(OR(A89<DATE(1900,1,1),A89>DATE(2100,12,31),A89>CONFIG!$B$5,C89<0,C89>1000000,D89<0,D89>1000000,E89<0,E89>1000000,E89>D89,ABS(F89)>1000000000,ABS(G89)>1000000000,ROUND(F89,2)<>F89,AND(G89<>"",ROUND(G89,2)<>G89)),"REVISAR VALOR","OK"))))),"REVISAR VALOR") -> OK
A90: 46259 | B90: PIL-LILA | C90: 2 | D90: 1 | E90: 1 | F90: 299 | H90: SYNTH-20260825 | I90: =IFERROR(IF(COUNTA(A90:H90)=0,"",IF(OR(A90="",B90="",C90="",D90="",E90="",F90=""),"FALTA CAMPO",IF(COUNTIFS($A$6:$A$1005,A90,$B$6:$B$1005,B90)>1,"DUPLICADO FECHA-SKU",IF(COUNTIF(CATALOGO!$A$6:$A$105,B90)<>1,"SKU NO VALIDO",IF(OR(A90<DATE(1900,1,1),A90>DATE(2100,12,31),A90>CONFIG!$B$5,C90<0,C90>1000000,D90<0,D90>1000000,E90<0,E90>1000000,E90>D90,ABS(F90)>1000000000,ABS(G90)>1000000000,ROUND(F90,2)<>F90,AND(G90<>"",ROUND(G90,2)<>G90)),"REVISAR VALOR","OK"))))),"REVISAR VALOR") -> OK
A91: 46260 | B91: PIL-LILA | C91: 2 | D91: 1 | E91: 0 | F91: 299 | H91: SYNTH-20260826 | I91: =IFERROR(IF(COUNTA(A91:H91)=0,"",IF(OR(A91="",B91="",C91="",D91="",E91="",F91=""),"FALTA CAMPO",IF(COUNTIFS($A$6:$A$1005,A91,$B$6:$B$1005,B91)>1,"DUPLICADO FECHA-SKU",IF(COUNTIF(CATALOGO!$A$6:$A$105,B91)<>1,"SKU NO VALIDO",IF(OR(A91<DATE(1900,1,1),A91>DATE(2100,12,31),A91>CONFIG!$B$5,C91<0,C91>1000000,D91<0,D91>1000000,E91<0,E91>1000000,E91>D91,ABS(F91)>1000000000,ABS(G91)>1000000000,ROUND(F91,2)<>F91,AND(G91<>"",ROUND(G91,2)<>G91)),"REVISAR VALOR","OK"))))),"REVISAR VALOR") -> OK
A92: 46261 | B92: PIL-LILA | C92: 2 | D92: 0 | E92: 0 | F92: 598 | H92: SYNTH-20260827 | I92: =IFERROR(IF(COUNTA(A92:H92)=0,"",IF(OR(A92="",B92="",C92="",D92="",E92="",F92=""),"FALTA CAMPO",IF(COUNTIFS($A$6:$A$1005,A92,$B$6:$B$1005,B92)>1,"DUPLICADO FECHA-SKU",IF(COUNTIF(CATALOGO!$A$6:$A$105,B92)<>1,"SKU NO VALIDO",IF(OR(A92<DATE(1900,1,1),A92>DATE(2100,12,31),A92>CONFIG!$B$5,C92<0,C92>1000000,D92<0,D92>1000000,E92<0,E92>1000000,E92>D92,ABS(F92)>1000000000,ABS(G92)>1000000000,ROUND(F92,2)<>F92,AND(G92<>"",ROUND(G92,2)<>G92)),"REVISAR VALOR","OK"))))),"REVISAR VALOR") -> OK
A93: 46262 | B93: PIL-LILA | C93: 2 | D93: 0 | E93: 0 | F93: 598 | H93: SYNTH-20260828 | I93: =IFERROR(IF(COUNTA(A93:H93)=0,"",IF(OR(A93="",B93="",C93="",D93="",E93="",F93=""),"FALTA CAMPO",IF(COUNTIFS($A$6:$A$1005,A93,$B$6:$B$1005,B93)>1,"DUPLICADO FECHA-SKU",IF(COUNTIF(CATALOGO!$A$6:$A$105,B93)<>1,"SKU NO VALIDO",IF(OR(A93<DATE(1900,1,1),A93>DATE(2100,12,31),A93>CONFIG!$B$5,C93<0,C93>1000000,D93<0,D93>1000000,E93<0,E93>1000000,E93>D93,ABS(F93)>1000000000,ABS(G93)>1000000000,ROUND(F93,2)<>F93,AND(G93<>"",ROUND(G93,2)<>G93)),"REVISAR VALOR","OK"))))),"REVISAR VALOR") -> OK
A94: 46263 | B94: PIL-LILA | C94: 2 | D94: 0 | E94: 0 | F94: 598 | H94: SYNTH-20260829 | I94: =IFERROR(IF(COUNTA(A94:H94)=0,"",IF(OR(A94="",B94="",C94="",D94="",E94="",F94=""),"FALTA CAMPO",IF(COUNTIFS($A$6:$A$1005,A94,$B$6:$B$1005,B94)>1,"DUPLICADO FECHA-SKU",IF(COUNTIF(CATALOGO!$A$6:$A$105,B94)<>1,"SKU NO VALIDO",IF(OR(A94<DATE(1900,1,1),A94>DATE(2100,12,31),A94>CONFIG!$B$5,C94<0,C94>1000000,D94<0,D94>1000000,E94<0,E94>1000000,E94>D94,ABS(F94)>1000000000,ABS(G94)>1000000000,ROUND(F94,2)<>F94,AND(G94<>"",ROUND(G94,2)<>G94)),"REVISAR VALOR","OK"))))),"REVISAR VALOR") -> OK
A95: 46264 | B95: PIL-LILA | C95: 2 | D95: 0 | E95: 0 | F95: 598 | H95: SYNTH-20260830 | I95: =IFERROR(IF(COUNTA(A95:H95)=0,"",IF(OR(A95="",B95="",C95="",D95="",E95="",F95=""),"FALTA CAMPO",IF(COUNTIFS($A$6:$A$1005,A95,$B$6:$B$1005,B95)>1,"DUPLICADO FECHA-SKU",IF(COUNTIF(CATALOGO!$A$6:$A$105,B95)<>1,"SKU NO VALIDO",IF(OR(A95<DATE(1900,1,1),A95>DATE(2100,12,31),A95>CONFIG!$B$5,C95<0,C95>1000000,D95<0,D95>1000000,E95<0,E95>1000000,E95>D95,ABS(F95)>1000000000,ABS(G95)>1000000000,ROUND(F95,2)<>F95,AND(G95<>"",ROUND(G95,2)<>G95)),"REVISAR VALOR","OK"))))),"REVISAR VALOR") -> OK
A96: 46265 | B96: PIL-LILA | C96: 2 | D96: 0 | E96: 0 | F96: 598 | H96: SYNTH-20260831 | I96: =IFERROR(IF(COUNTA(A96:H96)=0,"",IF(OR(A96="",B96="",C96="",D96="",E96="",F96=""),"FALTA CAMPO",IF(COUNTIFS($A$6:$A$1005,A96,$B$6:$B$1005,B96)>1,"DUPLICADO FECHA-SKU",IF(COUNTIF(CATALOGO!$A$6:$A$105,B96)<>1,"SKU NO VALIDO",IF(OR(A96<DATE(1900,1,1),A96>DATE(2100,12,31),A96>CONFIG!$B$5,C96<0,C96>1000000,D96<0,D96>1000000,E96<0,E96>1000000,E96>D96,ABS(F96)>1000000000,ABS(G96)>1000000000,ROUND(F96,2)<>F96,AND(G96<>"",ROUND(G96,2)<>G96)),"REVISAR VALOR","OK"))))),"REVISAR VALOR") -> OK
A97: 46266 | B97: PIL-LILA | C97: 1 | D97: 0 | E97: 0 | F97: 299 | H97: SYNTH-20260901 | I97: =IFERROR(IF(COUNTA(A97:H97)=0,"",IF(OR(A97="",B97="",C97="",D97="",E97="",F97=""),"FALTA CAMPO",IF(COUNTIFS($A$6:$A$1005,A97,$B$6:$B$1005,B97)>1,"DUPLICADO FECHA-SKU",IF(COUNTIF(CATALOGO!$A$6:$A$105,B97)<>1,"SKU NO VALIDO",IF(OR(A97<DATE(1900,1,1),A97>DATE(2100,12,31),A97>CONFIG!$B$5,C97<0,C97>1000000,D97<0,D97>1000000,E97<0,E97>1000000,E97>D97,ABS(F97)>1000000000,ABS(G97)>1000000000,ROUND(F97,2)<>F97,AND(G97<>"",ROUND(G97,2)<>G97)),"REVISAR VALOR","OK"))))),"REVISAR VALOR") -> OK
A98: 46267 | B98: PIL-LILA | C98: 1 | D98: 0 | E98: 0 | F98: 299 | H98: SYNTH-20260902 | I98: =IFERROR(IF(COUNTA(A98:H98)=0,"",IF(OR(A98="",B98="",C98="",D98="",E98="",F98=""),"FALTA CAMPO",IF(COUNTIFS($A$6:$A$1005,A98,$B$6:$B$1005,B98)>1,"DUPLICADO FECHA-SKU",IF(COUNTIF(CATALOGO!$A$6:$A$105,B98)<>1,"SKU NO VALIDO",IF(OR(A98<DATE(1900,1,1),A98>DATE(2100,12,31),A98>CONFIG!$B$5,C98<0,C98>1000000,D98<0,D98>1000000,E98<0,E98>1000000,E98>D98,ABS(F98)>1000000000,ABS(G98)>1000000000,ROUND(F98,2)<>F98,AND(G98<>"",ROUND(G98,2)<>G98)),"REVISAR VALOR","OK"))))),"REVISAR VALOR") -> OK
A99: 46268 | B99: PIL-LILA | C99: 1 | D99: 0 | E99: 0 | F99: 299 | H99: SYNTH-20260903 | I99: =IFERROR(IF(COUNTA(A99:H99)=0,"",IF(OR(A99="",B99="",C99="",D99="",E99="",F99=""),"FALTA CAMPO",IF(COUNTIFS($A$6:$A$1005,A99,$B$6:$B$1005,B99)>1,"DUPLICADO FECHA-SKU",IF(COUNTIF(CATALOGO!$A$6:$A$105,B99)<>1,"SKU NO VALIDO",IF(OR(A99<DATE(1900,1,1),A99>DATE(2100,12,31),A99>CONFIG!$B$5,C99<0,C99>1000000,D99<0,D99>1000000,E99<0,E99>1000000,E99>D99,ABS(F99)>1000000000,ABS(G99)>1000000000,ROUND(F99,2)<>F99,AND(G99<>"",ROUND(G99,2)<>G99)),"REVISAR VALOR","OK"))))),"REVISAR VALOR") -> OK
A100: 46269 | B100: PIL-LILA | C100: 1 | D100: 0 | E100: 0 | F100: 299 | H100: SYNTH-20260904 | I100: =IFERROR(IF(COUNTA(A100:H100)=0,"",IF(OR(A100="",B100="",C100="",D100="",E100="",F100=""),"FALTA CAMPO",IF(COUNTIFS($A$6:$A$1005,A100,$B$6:$B$1005,B100)>1,"DUPLICADO FECHA-SKU",IF(COUNTIF(CATALOGO!$A$6:$A$105,B100)<>1,"SKU NO VALIDO",IF(OR(A100<DATE(1900,1,1),A100>DATE(2100,12,31),A100>CONFIG!$B$5,C100<0,C100>1000000,D100<0,D100>1000000,E100<0,E100>1000000,E100>D100,ABS(F100)>1000000000,ABS(G100)>1000000000,ROUND(F100,2)<>F100,AND(G100<>"",ROUND(G100,2)<>G100)),"REVISAR VALOR","OK"))))),"REVISAR VALOR") -> OK
A101: 46270 | B101: PIL-LILA | C101: 1 | D101: 0 | E101: 0 | F101: 299 | H101: SYNTH-20260905 | I101: =IFERROR(IF(COUNTA(A101:H101)=0,"",IF(OR(A101="",B101="",C101="",D101="",E101="",F101=""),"FALTA CAMPO",IF(COUNTIFS($A$6:$A$1005,A101,$B$6:$B$1005,B101)>1,"DUPLICADO FECHA-SKU",IF(COUNTIF(CATALOGO!$A$6:$A$105,B101)<>1,"SKU NO VALIDO",IF(OR(A101<DATE(1900,1,1),A101>DATE(2100,12,31),A101>CONFIG!$B$5,C101<0,C101>1000000,D101<0,D101>1000000,E101<0,E101>1000000,E101>D101,ABS(F101)>1000000000,ABS(G101)>1000000000,ROUND(F101,2)<>F101,AND(G101<>"",ROUND(G101,2)<>G101)),"REVISAR VALOR","OK"))))),"REVISAR VALOR") -> OK
... A117: 46286 | B117: PIL-LILA | C117: 1 | D117: 0 | E117: 0 | F117: 299 | H117: SYNTH-20260921 | I117: =IFERROR(IF(COUNTA(A117:H117)=0,"",IF(OR(A117="",B117="",C117="",D117="",E117="",F117=""),"FALTA CAMPO",IF(COUNTIFS($A$6:$A$1005,A117,$B$6:$B$1005,B117)>1,"DUPLICADO FECHA-SKU",IF(COUNTIF(CATALOGO!$A$6:$A$105,B117)<>1,"SKU NO VALIDO",IF(OR(A117<DATE(1900,1,1),A117>DATE(2100,12,31),A117>CONFIG!$B$5,C117<0,C117>1000000,D117<0,D117>1000000,E117<0,E117>1000000,E117>D117,ABS(F117)>1000000000,ABS(G117)>1000000000,ROUND(F117,2)<>F117,AND(G117<>"",ROUND(G117,2)<>G117)),"REVISAR VALOR","OK"))))),"REVISAR VALOR") -> OK
A118: 46259 | B118: PIL-VERDE | C118: 2 | D118: 1 | E118: 1 | F118: 299 | G118: 104 | H118: SYNTH-20260825 | I118: =IFERROR(IF(COUNTA(A118:H118)=0,"",IF(OR(A118="",B118="",C118="",D118="",E118="",F118=""),"FALTA CAMPO",IF(COUNTIFS($A$6:$A$1005,A118,$B$6:$B$1005,B118)>1,"DUPLICADO FECHA-SKU",IF(COUNTIF(CATALOGO!$A$6:$A$105,B118)<>1,"SKU NO VALIDO",IF(OR(A118<DATE(1900,1,1),A118>DATE(2100,12,31),A118>CONFIG!$B$5,C118<0,C118>1000000,D118<0,D118>1000000,E118<0,E118>1000000,E118>D118,ABS(F118)>1000000000,ABS(G118)>1000000000,ROUND(F118,2)<>F118,AND(G118<>"",ROUND(G118,2)<>G118)),"REVISAR VALOR","OK"))))),"REVISAR VALOR") -> OK
A119: 46260 | B119: PIL-VERDE | C119: 2 | D119: 1 | E119: 0 | F119: 299 | G119: 208 | H119: SYNTH-20260826 | I119: =IFERROR(IF(COUNTA(A119:H119)=0,"",IF(OR(A119="",B119="",C119="",D119="",E119="",F119=""),"FALTA CAMPO",IF(COUNTIFS($A$6:$A$1005,A119,$B$6:$B$1005,B119)>1,"DUPLICADO FECHA-SKU",IF(COUNTIF(CATALOGO!$A$6:$A$105,B119)<>1,"SKU NO VALIDO",IF(OR(A119<DATE(1900,1,1),A119>DATE(2100,12,31),A119>CONFIG!$B$5,C119<0,C119>1000000,D119<0,D119>1000000,E119<0,E119>1000000,E119>D119,ABS(F119)>1000000000,ABS(G119)>1000000000,ROUND(F119,2)<>F119,AND(G119<>"",ROUND(G119,2)<>G119)),"REVISAR VALOR","OK"))))),"REVISAR VALOR") -> OK
A120: 46261 | B120: PIL-VERDE | C120: 2 | D120: 0 | E120: 0 | F120: 598 | G120: 208 | H120: SYNTH-20260827 | I120: =IFERROR(IF(COUNTA(A120:H120)=0,"",IF(OR(A120="",B120="",C120="",D120="",E120="",F120=""),"FALTA CAMPO",IF(COUNTIFS($A$6:$A$1005,A120,$B$6:$B$1005,B120)>1,"DUPLICADO FECHA-SKU",IF(COUNTIF(CATALOGO!$A$6:$A$105,B120)<>1,"SKU NO VALIDO",IF(OR(A120<DATE(1900,1,1),A120>DATE(2100,12,31),A120>CONFIG!$B$5,C120<0,C120>1000000,D120<0,D120>1000000,E120<0,E120>1000000,E120>D120,ABS(F120)>1000000000,ABS(G120)>1000000000,ROUND(F120,2)<>F120,AND(G120<>"",ROUND(G120,2)<>G120)),"REVISAR VALOR","OK"))))),"REVISAR VALOR") -> OK
A121: 46262 | B121: PIL-VERDE | C121: 2 | D121: 0 | E121: 0 | F121: 598 | G121: 208 | H121: SYNTH-20260828 | I121: =IFERROR(IF(COUNTA(A121:H121)=0,"",IF(OR(A121="",B121="",C121="",D121="",E121="",F121=""),"FALTA CAMPO",IF(COUNTIFS($A$6:$A$1005,A121,$B$6:$B$1005,B121)>1,"DUPLICADO FECHA-SKU",IF(COUNTIF(CATALOGO!$A$6:$A$105,B121)<>1,"SKU NO VALIDO",IF(OR(A121<DATE(1900,1,1),A121>DATE(2100,12,31),A121>CONFIG!$B$5,C121<0,C121>1000000,D121<0,D121>1000000,E121<0,E121>1000000,E121>D121,ABS(F121)>1000000000,ABS(G121)>1000000000,ROUND(F121,2)<>F121,AND(G121<>"",ROUND(G121,2)<>G121)),"REVISAR VALOR","OK"))))),"REVISAR VALOR") -> OK
A122: 46263 | B122: PIL-VERDE | C122: 2 | D122: 0 | E122: 0 | F122: 598 | G122: 208 | H122: SYNTH-20260829 | I122: =IFERROR(IF(COUNTA(A122:H122)=0,"",IF(OR(A122="",B122="",C122="",D122="",E122="",F122=""),"FALTA CAMPO",IF(COUNTIFS($A$6:$A$1005,A122,$B$6:$B$1005,B122)>1,"DUPLICADO FECHA-SKU",IF(COUNTIF(CATALOGO!$A$6:$A$105,B122)<>1,"SKU NO VALIDO",IF(OR(A122<DATE(1900,1,1),A122>DATE(2100,12,31),A122>CONFIG!$B$5,C122<0,C122>1000000,D122<0,D122>1000000,E122<0,E122>1000000,E122>D122,ABS(F122)>1000000000,ABS(G122)>1000000000,ROUND(F122,2)<>F122,AND(G122<>"",ROUND(G122,2)<>G122)),"REVISAR VALOR","OK"))))),"REVISAR VALOR") -> OK
A123: 46264 | B123: PIL-VERDE | C123: 2 | D123: 0 | E123: 0 | F123: 598 | G123: 208 | H123: SYNTH-20260830 | I123: =IFERROR(IF(COUNTA(A123:H123)=0,"",IF(OR(A123="",B123="",C123="",D123="",E123="",F123=""),"FALTA CAMPO",IF(COUNTIFS($A$6:$A$1005,A123,$B$6:$B$1005,B123)>1,"DUPLICADO FECHA-SKU",IF(COUNTIF(CATALOGO!$A$6:$A$105,B123)<>1,"SKU NO VALIDO",IF(OR(A123<DATE(1900,1,1),A123>DATE(2100,12,31),A123>CONFIG!$B$5,C123<0,C123>1000000,D123<0,D123>1000000,E123<0,E123>1000000,E123>D123,ABS(F123)>1000000000,ABS(G123)>1000000000,ROUND(F123,2)<>F123,AND(G123<>"",ROUND(G123,2)<>G123)),"REVISAR VALOR","OK"))))),"REVISAR VALOR") -> OK
A124: 46265 | B124: PIL-VERDE | C124: 2 | D124: 0 | E124: 0 | F124: 598 | G124: 208 | H124: SYNTH-20260831 | I124: =IFERROR(IF(COUNTA(A124:H124)=0,"",IF(OR(A124="",B124="",C124="",D124="",E124="",F124=""),"FALTA CAMPO",IF(COUNTIFS($A$6:$A$1005,A124,$B$6:$B$1005,B124)>1,"DUPLICADO FECHA-SKU",IF(COUNTIF(CATALOGO!$A$6:$A$105,B124)<>1,"SKU NO VALIDO",IF(OR(A124<DATE(1900,1,1),A124>DATE(2100,12,31),A124>CONFIG!$B$5,C124<0,C124>1000000,D124<0,D124>1000000,E124<0,E124>1000000,E124>D124,ABS(F124)>1000000000,ABS(G124)>1000000000,ROUND(F124,2)<>F124,AND(G124<>"",ROUND(G124,2)<>G124)),"REVISAR VALOR","OK"))))),"REVISAR VALOR") -> OK
A125: 46266 | B125: PIL-VERDE | C125: 2 | D125: 0 | E125: 0 | F125: 598 | G125: 208 | H125: SYNTH-20260901 | I125: =IFERROR(IF(COUNTA(A125:H125)=0,"",IF(OR(A125="",B125="",C125="",D125="",E125="",F125=""),"FALTA CAMPO",IF(COUNTIFS($A$6:$A$1005,A125,$B$6:$B$1005,B125)>1,"DUPLICADO FECHA-SKU",IF(COUNTIF(CATALOGO!$A$6:$A$105,B125)<>1,"SKU NO VALIDO",IF(OR(A125<DATE(1900,1,1),A125>DATE(2100,12,31),A125>CONFIG!$B$5,C125<0,C125>1000000,D125<0,D125>1000000,E125<0,E125>1000000,E125>D125,ABS(F125)>1000000000,ABS(G125)>1000000000,ROUND(F125,2)<>F125,AND(G125<>"",ROUND(G125,2)<>G125)),"REVISAR VALOR","OK"))))),"REVISAR VALOR") -> OK
A126: 46267 | B126: PIL-VERDE | C126: 2 | D126: 0 | E126: 0 | F126: 598 | G126: 208 | H126: SYNTH-20260902 | I126: =IFERROR(IF(COUNTA(A126:H126)=0,"",IF(OR(A126="",B126="",C126="",D126="",E126="",F126=""),"FALTA CAMPO",IF(COUNTIFS($A$6:$A$1005,A126,$B$6:$B$1005,B126)>1,"DUPLICADO FECHA-SKU",IF(COUNTIF(CATALOGO!$A$6:$A$105,B126)<>1,"SKU NO VALIDO",IF(OR(A126<DATE(1900,1,1),A126>DATE(2100,12,31),A126>CONFIG!$B$5,C126<0,C126>1000000,D126<0,D126>1000000,E126<0,E126>1000000,E126>D126,ABS(F126)>1000000000,ABS(G126)>1000000000,ROUND(F126,2)<>F126,AND(G126<>"",ROUND(G126,2)<>G126)),"REVISAR VALOR","OK"))))),"REVISAR VALOR") -> OK
A127: 46268 | B127: PIL-VERDE | C127: 2 | D127: 0 | E127: 0 | F127: 598 | G127: 208 | H127: SYNTH-20260903 | I127: =IFERROR(IF(COUNTA(A127:H127)=0,"",IF(OR(A127="",B127="",C127="",D127="",E127="",F127=""),"FALTA CAMPO",IF(COUNTIFS($A$6:$A$1005,A127,$B$6:$B$1005,B127)>1,"DUPLICADO FECHA-SKU",IF(COUNTIF(CATALOGO!$A$6:$A$105,B127)<>1,"SKU NO VALIDO",IF(OR(A127<DATE(1900,1,1),A127>DATE(2100,12,31),A127>CONFIG!$B$5,C127<0,C127>1000000,D127<0,D127>1000000,E127<0,E127>1000000,E127>D127,ABS(F127)>1000000000,ABS(G127)>1000000000,ROUND(F127,2)<>F127,AND(G127<>"",ROUND(G127,2)<>G127)),"REVISAR VALOR","OK"))))),"REVISAR VALOR") -> OK
A128: 46269 | B128: PIL-VERDE | C128: 2 | D128: 0 | E128: 0 | F128: 598 | G128: 208 | H128: SYNTH-20260904 | I128: =IFERROR(IF(COUNTA(A128:H128)=0,"",IF(OR(A128="",B128="",C128="",D128="",E128="",F128=""),"FALTA CAMPO",IF(COUNTIFS($A$6:$A$1005,A128,$B$6:$B$1005,B128)>1,"DUPLICADO FECHA-SKU",IF(COUNTIF(CATALOGO!$A$6:$A$105,B128)<>1,"SKU NO VALIDO",IF(OR(A128<DATE(1900,1,1),A128>DATE(2100,12,31),A128>CONFIG!$B$5,C128<0,C128>1000000,D128<0,D128>1000000,E128<0,E128>1000000,E128>D128,ABS(F128)>1000000000,ABS(G128)>1000000000,ROUND(F128,2)<>F128,AND(G128<>"",ROUND(G128,2)<>G128)),"REVISAR VALOR","OK"))))),"REVISAR VALOR") -> OK
...

Sheet STOCK
A1: STOCK Y ESCENARIO DE COMPRA
A2: Azul = captura editable · Verde = vínculo entre hojas · Negro = cálculo. Blanco significa desconocido; cero es un valor explícito. La propuesta es condicional y nunca crea una orden. El efectivo usa compra + flete de entrada, sin empaque.
A5: SKU | B5: Fecha conteo | C5: Existencia | D5: Reservado | E5: En tránsito | F5: ETA | G5: Tránsito confirmado | H5: Días disponibilidad observada | I5: Cantidad elegida | J5: Fecha pago | K5: Estado evidencia | L5: Disponible | M5: Consumo diario | N5: Tránsito elegible | O5: Necesidad | P5: Propuesta condicional | Q5: Costo compra+flete/u (MXN pesos) | R5: Efectivo compra (MXN pesos) | S5: Estado plan
